export const getPendingContent = async (req, res) => {
    try {
      // Business logic for fetching pending content
    } catch (error) {
      console.error('Error in getPendingContent:', error.message);
      res.status(500).json({ error: 'An error occurred while fetching pending content.' });
    }
  };
  
  export const approveContent = async (req, res) => {
    try {
      // Business logic for approving content
    } catch (error) {
      console.error('Error in approveContent:', error.message);
      res.status(500).json({ error: 'An error occurred while approving the content.' });
    }
  };
  
  export const rejectContent = async (req, res) => {
    try {
      // Business logic for rejecting content
    } catch (error) {
      console.error('Error in rejectContent:', error.message);
      res.status(500).json({ error: 'An error occurred while rejecting the content.' });
    }
  };
  
  export const manageUsers = async (req, res) => {
    try {
      // Business logic for managing users
    } catch (error) {
      console.error('Error in manageUsers:', error.message);
      res.status(500).json({ error: 'An error occurred while managing users.' });
    }
  };
  